Workbook

Sheet Financials>

Sheet Data

Sheet HistoricalFS
B2: ="Historical Financials Statements - "& 'Data Sheet'!B1
B3: Years | C3: ='Data Sheet'!B16 | D3: ='Data Sheet'!C16 | E3: ='Data Sheet'!D16 | F3: ='Data Sheet'!E16 | G3: ='Data Sheet'!F16 | H3: ='Data Sheet'!G16 | I3: ='Data Sheet'!H16 | J3: ='Data Sheet'!I16 | ... L3: ='Data Sheet'!K16 | M3: LTM
A5: # | B5: Income Statement
B6: Sales | C6: =IFERROR('Data Sheet'!B17,0) | D6: =IFERROR('Data Sheet'!C17,0) | E6: =IFERROR('Data Sheet'!D17,0) | F6: =IFERROR('Data Sheet'!E17,0) | G6: =IFERROR('Data Sheet'!F17,0) | H6: =IFERROR('Data Sheet'!G17,0) | I6: =IFERROR('Data Sheet'!H17,0) | J6: =IFERROR('Data Sheet'!I17,0) | ... L6: =IFERROR('Data Sheet'!K17,0) | M6: =IFERROR(SUM('Data Sheet'!H42:K42),0)
B7: Sales Growth | C7: - | D7: =D6/C6-1 | E7: =E6/D6-1 | F7: =F6/E6-1 | G7: =G6/F6-1 | H7: =H6/G6-1 | I7: =I6/H6-1 | J7: =J6/I6-1 | K7: =K6/J6-1 | ... M7: =M6/L6-1
B9: COGS | C9: =IFERROR(SUM('Data Sheet'!B18,'Data Sheet'!B20:B22)-1*'Data Sheet'!B19,0) | D9: =IFERROR(SUM('Data Sheet'!C18,'Data Sheet'!C20:C22)-1*'Data Sheet'!C19,0) | E9: =IFERROR(SUM('Data Sheet'!D18,'Data Sheet'!D20:D22)-1*'Data Sheet'!D19,0) | F9: =IFERROR(SUM('Data Sheet'!E18,'Data Sheet'!E20:E22)-1*'Data Sheet'!E19,0) | G9: =IFERROR(SUM('Data Sheet'!F18,'Data Sheet'!F20:F22)-1*'Data Sheet'!F19,0) | H9: =IFERROR(SUM('Data Sheet'!G18,'Data Sheet'!G20:G22)-1*'Data Sheet'!G19,0) | I9: =IFERROR(SUM('Data Sheet'!H18,'Data Sheet'!H20:H22)-1*'Data Sheet'!H19,0) | J9: =IFERROR(SUM('Data Sheet'!I18,'Data Sheet'!I20:I22)-1*'Data Sheet'!I19,0) | ... L9: =IFERROR(SUM('Data Sheet'!K18,'Data Sheet'!K20:K22)-1*'Data Sheet'!K19,0) | M9: =IFERROR(SUM('Data Sheet'!H43:K43),0)
B10: COGS % sales | C10: =C9/C6 | D10: =D9/D6 | E10: =E9/E6 | F10: =F9/F6 | G10: =G9/G6 | H10: =H9/H6 | I10: =I9/I6 | J10: =J9/J6 | ... M10: =M9/M6
B12: Gross Profit | C12: =C6-C9 | D12: =D6-D9 | E12: =E6-E9 | F12: =F6-F9 | G12: =G6-G9 | H12: =H6-H9 | I12: =I6-I9 | J12: =J6-J9 | ... M12: =M6-M9
B13: Gross Margin | C13: =C12/C6 | D13: =D12/D6 | E13: =E12/E6 | F13: =F12/F6 | G13: =G12/G6 | H13: =H12/H6 | I13: =I12/I6 | J13: =J12/J6 | ... M13: =M12/M6
B15: Selling and General Expenses | C15: =IFERROR(SUM('Data Sheet'!B23:B24),0) | D15: =IFERROR(SUM('Data Sheet'!C23:C24),0) | E15: =IFERROR(SUM('Data Sheet'!D23:D24),0) | F15: =IFERROR(SUM('Data Sheet'!E23:E24),0) | G15: =IFERROR(SUM('Data Sheet'!F23:F24),0) | H15: =IFERROR(SUM('Data Sheet'!G23:G24),0) | I15: =IFERROR(SUM('Data Sheet'!H23:H24),0) | J15: =IFERROR(SUM('Data Sheet'!I23:I24),0) | ... L15: =IFERROR(SUM('Data Sheet'!K23:K24),0)
B16: S&G Exp % sales | C16: =C15/C6 | D16: =D15/D6 | E16: =E15/E6 | F16: =F15/F6 | G16: =G15/G6 | H16: =H15/H6 | I16: =I15/I6 | J16: =J15/J6 | ... M16: =M15/M6
B18: EBITDA | C18: =C12-C15 | D18: =D12-D15 | E18: =E12-E15 | F18: =F12-F15 | G18: =G12-G15 | H18: =H12-H15 | I18: =I12-I15 | J18: =J12-J15 | ... L18: =L12-L15 | M18: =IFERROR(SUM('Data Sheet'!H46:K46,'Data Sheet'!H48:K48,'Data Sheet'!H45:K45),0)
B19: EBITDA%sales | C19: =C18/C6 | D19: =D18/D6 | E19: =E18/E6 | F19: =F18/F6 | G19: =G18/G6 | H19: =H18/H6 | I19: =I18/I6 | J19: =J18/J6 | ... M19: =M18/M6
B21: Interest | C21: =IFERROR(SUM('Data Sheet'!B27),0) | D21: =IFERROR(SUM('Data Sheet'!C27),0) | E21: =IFERROR(SUM('Data Sheet'!D27),0) | F21: =IFERROR(SUM('Data Sheet'!E27),0) | G21: =IFERROR(SUM('Data Sheet'!F27),0) | H21: =IFERROR(SUM('Data Sheet'!G27),0) | I21: =IFERROR(SUM('Data Sheet'!H27),0) | J21: =IFERROR(SUM('Data Sheet'!I27),0) | ... L21: =IFERROR(SUM('Data Sheet'!K27),0) | M21: =IFERROR(SUM('Data Sheet'!H46:K46),0)
B22: Interest % sales | C22: =C21/C6 | D22: =D21/D6 | E22: =E21/E6 | F22: =F21/F6 | G22: =G21/G6 | H22: =H21/H6 | I22: =I21/I6 | J22: =J21/J6 | ... M22: =M21/M6
B24: Depreciation | C24: =IFERROR('Data Sheet'!B26,0) | D24: =IFERROR('Data Sheet'!C26,0) | E24: =IFERROR('Data Sheet'!D26,0) | F24: =IFERROR('Data Sheet'!E26,0) | G24: =IFERROR('Data Sheet'!F26,0) | H24: =IFERROR('Data Sheet'!G26,0) | I24: =IFERROR('Data Sheet'!H26,0) | J24: =IFERROR('Data Sheet'!I26,0) | ... L24: =IFERROR('Data Sheet'!K26,0) | M24: =IFERROR(SUM('Data Sheet'!H45:K45),0)
B25: Depreciation % sales | C25: =C24/C6 | D25: =D24/D6 | E25: =E24/E6 | F25: =F24/F6 | G25: =G24/G6 | H25: =H24/H6 | I25: =I24/I6 | J25: =J24/J6 | ... M25: =M24/M6
B27: Earnings Before Tax | C27: =IFERROR(SUM(C18,C21,C24),0) | D27: =IFERROR(SUM(D18,D21,D24),0) | E27: =IFERROR(SUM(E18,E21,E24),0) | F27: =IFERROR(SUM(F18,F21,F24),0) | G27: =IFERROR(SUM(G18,G21,G24),0) | H27: =IFERROR(SUM(H18,H21,H24),0) | I27: =IFERROR(SUM(I18,I21,I24),0) | J27: =IFERROR(SUM(J18,J21,J24),0) | ... M27: =IFERROR(SUM(M18,M21,M24),0)
B28: EBT%sales | C28: =C27/C6 | D28: =D27/D6 | E28: =E27/E6 | F28: =F27/F6 | G28: =G27/G6 | H28: =H27/H6 | I28: =I27/I6 | J28: =J27/J6 | ... M28: =M27/M6
B30: Tax | C30: =IFERROR('Data Sheet'!B29,0) | D30: =IFERROR('Data Sheet'!C29,0) | E30: =IFERROR('Data Sheet'!D29,0) | F30: =IFERROR('Data Sheet'!E29,0) | G30: =IFERROR('Data Sheet'!F29,0) | H30: =IFERROR('Data Sheet'!G29,0) | I30: =IFERROR('Data Sheet'!H29,0) | J30: =IFERROR('Data Sheet'!I29,0) | ... L30: =IFERROR('Data Sheet'!K29,0) | M30: =IFERROR(SUM('Data Sheet'!H48:K48),0)
B31: Effective Tax rate | C31: =C30/C27 | D31: =D30/D27 | E31: =E30/E27 | F31: =F30/F27 | G31: =G30/G27 | H31: =H30/H27 | I31: =I30/I27 | J31: =J30/J27 | ... M31: =M30/M27
B33: Net Profit | C33: =IFERROR(C27-C30,0) | D33: =IFERROR(D27-D30,0) | E33: =IFERROR(E27-E30,0) | F33: =IFERROR(F27-F30,0) | G33: =IFERROR(G27-G30,0) | H33: =IFERROR(H27-H30,0) | I33: =IFERROR(I27-I30,0) | J33: =IFERROR(J27-J30,0) | ... M33: =IFERROR(M27-M30,0)
B34: Net margin | C34: =C33/C6 | D34: =D33/D6 | E34: =E33/E6 | F34: =F33/F6 | G34: =G33/G6 | H34: =H33/H6 | I34: =I33/I6 | J34: =J33/J6 | ... M34: =M33/M6
B36: No of Equity Shares | C36: =IFERROR('Data Sheet'!B93,0) | D36: =IFERROR('Data Sheet'!C93,0) | E36: =IFERROR('Data Sheet'!D93,0) | F36: =IFERROR('Data Sheet'!E93,0) | G36: =IFERROR('Data Sheet'!F93,0) | H36: =IFERROR('Data Sheet'!G93,0) | I36: =IFERROR('Data Sheet'!H93,0) | J36: =IFERROR('Data Sheet'!I93,0) | ... M36: =IFERROR('Data Sheet'!L93,0)
B38: EPS | C38: =IFERROR(C33/C36,0) | D38: =IFERROR(D33/D36,0) | E38: =IFERROR(E33/E36,0) | F38: =IFERROR(F33/F36,0) | G38: =IFERROR(G33/G36,0) | H38: =IFERROR(H33/H36,0) | I38: =IFERROR(I33/I36,0) | J38: =IFERROR(J33/J36,0) | ... M38: =IFERROR(M33/M36,0)
B39: EPS Growth | D39: =IFERROR(D38/C38-1,0) | E39: =IFERROR(E38/D38-1,0) | F39: =IFERROR(F38/E38-1,0) | G39: =IFERROR(G38/F38-1,0) | H39: =IFERROR(H38/G38-1,0) | I39: =IFERROR(I38/H38-1,0) | J39: =IFERROR(J38/I38-1,0) | K39: =IFERROR(K38/J38-1,0) | ... M39: =IFERROR(M38/L38-1,0)
B41: Dividend per share | C41: =IFERROR('Data Sheet'!B31/HistoricalFS!C36,0) | D41: =IFERROR('Data Sheet'!C31/HistoricalFS!D36,0) | E41: =IFERROR('Data Sheet'!D31/HistoricalFS!E36,0) | F41: =IFERROR('Data Sheet'!E31/HistoricalFS!F36,0) | G41: =IFERROR('Data Sheet'!F31/HistoricalFS!G36,0) | H41: =IFERROR('Data Sheet'!G31/HistoricalFS!H36,0) | I41: =IFERROR('Data Sheet'!H31/HistoricalFS!I36,0) | J41: =IFERROR('Data Sheet'!I31/HistoricalFS!J36,0) | ... M41: =IFERROR('Data Sheet'!L31/HistoricalFS!M36,0)
B42: Dividend payout ratio | C42: =IFERROR(C41/C38,0) | D42: =IFERROR(D41/D38,0) | E42: =IFERROR(E41/E38,0) | F42: =IFERROR(F41/F38,0) | G42: =IFERROR(G41/G38,0) | H42: =IFERROR(H41/H38,0) | I42: =IFERROR(I41/I38,0) | J42: =IFERROR(J41/J38,0) | ... M42: =IFERROR(M41/M38,0)
B44: Retained Earnings | C44: =IFERROR(IF(C38>C41,1-D42,0),0) | D44: =IFERROR(IF(D38>D41,1-E42,0),0) | E44: =IFERROR(IF(E38>E41,1-F42,0),0) | F44: =IFERROR(IF(F38>F41,1-G42,0),0) | G44: =IFERROR(IF(G38>G41,1-H42,0),0) | H44: =IFERROR(IF(H38>H41,1-I42,0),0) | I44: =IFERROR(IF(I38>I41,1-J42,0),0) | J44: =IFERROR(IF(J38>J41,1-K42,0),0) | ... M44: =IFERROR(IF(M38>M41,1-N42,0),0)
A47: # | B47: Balance Sheet
B48: Equity Share Capital | C48: =IFERROR('Data Sheet'!B57,0) | D48: =IFERROR('Data Sheet'!C57,0) | E48: =IFERROR('Data Sheet'!D57,0) | F48: =IFERROR('Data Sheet'!E57,0) | G48: =IFERROR('Data Sheet'!F57,0) | H48: =IFERROR('Data Sheet'!G57,0) | I48: =IFERROR('Data Sheet'!H57,0) | J48: =IFERROR('Data Sheet'!I57,0) | ... L48: =IFERROR('Data Sheet'!K57,0)
B49: Reserves | C49: =IFERROR('Data Sheet'!B58,0) | D49: =IFERROR('Data Sheet'!C58,0) | E49: =IFERROR('Data Sheet'!D58,0) | F49: =IFERROR('Data Sheet'!E58,0) | G49: =IFERROR('Data Sheet'!F58,0) | H49: =IFERROR('Data Sheet'!G58,0) | I49: =IFERROR('Data Sheet'!H58,0) | J49: =IFERROR('Data Sheet'!I58,0) | ... L49: =IFERROR('Data Sheet'!K58,0)
B50: Borrowings | C50: =IFERROR('Data Sheet'!B59,0) | D50: =IFERROR('Data Sheet'!C59,0) | E50: =IFERROR('Data Sheet'!D59,0) | F50: =IFERROR('Data Sheet'!E59,0) | G50: =IFERROR('Data Sheet'!F59,0) | H50: =IFERROR('Data Sheet'!G59,0) | I50: =IFERROR('Data Sheet'!H59,0) | J50: =IFERROR('Data Sheet'!I59,0) | ... L50: =IFERROR('Data Sheet'!K59,0)
B51: Other Liabilities | C51: =IFERROR('Data Sheet'!B60,0) | D51: =IFERROR('Data Sheet'!C60,0) | E51: =IFERROR('Data Sheet'!D60,0) | F51: =IFERROR('Data Sheet'!E60,0) | G51: =IFERROR('Data Sheet'!F60,0) | H51: =IFERROR('Data Sheet'!G60,0) | I51: =IFERROR('Data Sheet'!H60,0) | J51: =IFERROR('Data Sheet'!I60,0) | ... L51: =IFERROR('Data Sheet'!K60,0)
B52: Total Liablities | C52: =IFERROR('Data Sheet'!B61,0) | D52: =IFERROR('Data Sheet'!C61,0) | E52: =IFERROR('Data Sheet'!D61,0) | F52: =IFERROR('Data Sheet'!E61,0) | G52: =IFERROR('Data Sheet'!F61,0) | H52: =IFERROR('Data Sheet'!G61,0) | I52: =IFERROR('Data Sheet'!H61,0) | J52: =IFERROR('Data Sheet'!I61,0) | ... L52: =IFERROR('Data Sheet'!K61,0)
B54: Fixex Assets Net Block | C54: =IFERROR('Data Sheet'!B62,0) | D54: =IFERROR('Data Sheet'!C62,0) | E54: =IFERROR('Data Sheet'!D62,0) | F54: =IFERROR('Data Sheet'!E62,0) | G54: =IFERROR('Data Sheet'!F62,0) | H54: =IFERROR('Data Sheet'!G62,0) | I54: =IFERROR('Data Sheet'!H62,0) | J54: =IFERROR('Data Sheet'!I62,0) | ... L54: =IFERROR('Data Sheet'!K62,0)
B55: Capital Work in Progress | C55: =IFERROR('Data Sheet'!B63,0) | D55: =IFERROR('Data Sheet'!C63,0) | E55: =IFERROR('Data Sheet'!D63,0) | F55: =IFERROR('Data Sheet'!E63,0) | G55: =IFERROR('Data Sheet'!F63,0) | H55: =IFERROR('Data Sheet'!G63,0) | I55: =IFERROR('Data Sheet'!H63,0) | J55: =IFERROR('Data Sheet'!I63,0) | ... L55: =IFERROR('Data Sheet'!K63,0)
B56: Investments | C56: =IFERROR('Data Sheet'!B64,0) | D56: =IFERROR('Data Sheet'!C64,0) | E56: =IFERROR('Data Sheet'!D64,0) | F56: =IFERROR('Data Sheet'!E64,0) | G56: =IFERROR('Data Sheet'!F64,0) | H56: =IFERROR('Data Sheet'!G64,0) | I56: =IFERROR('Data Sheet'!H64,0) | J56: =IFERROR('Data Sheet'!I64,0) | ... L56: =IFERROR('Data Sheet'!K64,0)
B57: Other Assets | C57: =IFERROR('Data Sheet'!B65-SUM('Data Sheet'!B67:B69),0) | D57: =IFERROR('Data Sheet'!C65-SUM('Data Sheet'!C67:C69),0) | E57: =IFERROR('Data Sheet'!D65-SUM('Data Sheet'!D67:D69),0) | F57: =IFERROR('Data Sheet'!E65-SUM('Data Sheet'!E67:E69),0) | G57: =IFERROR('Data Sheet'!F65-SUM('Data Sheet'!F67:F69),0) | H57: =IFERROR('Data Sheet'!G65-SUM('Data Sheet'!G67:G69),0) | I57: =IFERROR('Data Sheet'!H65-SUM('Data Sheet'!H67:H69),0) | J57: =IFERROR('Data Sheet'!I65-SUM('Data Sheet'!I67:I69),0) | ... L57: =IFERROR('Data Sheet'!K65-SUM('Data Sheet'!K67:K69),0)
B58: Total Non Current Assets | C58: =SUM(C54:C57) | D58: =SUM(D54:D57) | E58: =SUM(E54:E57) | F58: =SUM(F54:F57) | G58: =SUM(G54:G57) | H58: =SUM(H54:H57) | I58: =SUM(I54:I57) | J58: =SUM(J54:J57) | ... L58: =SUM(L54:L57)
...

Sheet Data Sheet
A1: COMPANY NAME | B1: NESTLE INDIA LTD | E1: =IF(B2<>B3, "A NEW VERSION OF THE WORKSHEET IS AVAILABLE", "")
A2: LATEST VERSION | B2: 2.1 | E2: PLEASE DO NOT MAKE ANY CHANGES TO THIS SHEET
A3: CURRENT VERSION | B3: 2.1
A5: META
A6: Number of shares | B6: =IF(B9>0, B9/B8, 0)
A7: Face Value | B7: 1
A8: Current Price | B8: 1246.9
A9: Market Capitalization | B9: 240441.51
A15: PROFIT & LOSS
A16: Report Date | B16: 42735 | C16: 43100 | D16: 43465 | E16: 43830 | F16: 44196 | G16: 44561 | H16: 44926 | I16: 45291 | J16: 45382 | K16: 45747
A17: Sales | B17: 9141.34 | C17: 10009.6 | D17: 11292.27 | E17: 12368.9 | F17: 13350.03 | G17: 14740.59 | H17: 16896.96 | I17: 19126.3 | J17: 24393.89 | K17: 20201.56
A18: Raw Material Cost | B18: 3227.26 | C18: 3696.99 | D18: 3829.22 | E18: 4520.91 | F18: 4901.74 | G18: 5301.26 | H18: 6660.42 | I18: 8472.72 | J18: 9201.11 | K18: 7646.63
A19: Change in Inventory | B19: 7.66 | C19: 79.56 | D19: 6.01 | E19: 144.19 | F19: 69.33 | G19: 67.59 | H19: 250.27 | I19: 40.01 | J19: 45.68 | K19: 139.66
A20: Power and Fuel | B20: 232.79 | C20: 288.44 | D20: 344.18 | E20: 340.53 | F20: 313.68 | G20: 408.06 | H20: 572.61 | J20: 674.83 | K20: 536.65
A21: Other Mfr. Exp | B21: 850.85 | C21: 897.84 | D21: 949.86 | E21: 1028.55 | F21: 1040.36 | G21: 1349.48 | H21: 1603.48 | J21: 1935.4 | K21: 1579.8
A22: Employee Cost | B22: 901.57 | C22: 1017.45 | D22: 1124.15 | E22: 1258.17 | F22: 1500.95 | G22: 1529.94 | H22: 1635.46 | I22: 1849.18 | J22: 2336.06 | K22: 2023.71
A23: Selling and admin | B23: 1751.78 | C23: 1823.98 | D23: 2145.82 | E23: 2226.13 | F23: 2246.9 | G23: 2902.12 | H23: 3192.15 | J23: 4837.58 | K23: 4121.66
A24: Other Expenses | B24: 334.91 | C24: 267.93 | D24: 287.4 | E24: 212.92 | F24: 214.23 | G24: -245.08 | H24: -223.18 | I24: 4373.42 | J24: -388.53 | K24: -338.56
A25: Other Income | B25: 140.12 | C25: 176.92 | D25: 258.92 | E25: 246.88 | F25: 145.85 | G25: -112.38 | H25: 107.26 | I25: 115.5 | J25: 158.99 | K25: 352.06
A26: Depreciation | B26: 353.67 | C26: 342.25 | D26: 335.67 | E26: 370.15 | F26: 370.38 | G26: 391.02 | H26: 403.01 | I26: 428.91 | J26: 567.75 | K26: 539.92
A27: Interest | B27: 90.91 | C27: 91.9 | D27: 111.95 | E27: 129.12 | F27: 164.18 | G27: 201.68 | H27: 154.57 | I27: 119.29 | J27: 145.49 | K27: 136
A28: Profit before tax | B28: 1545.38 | C28: 1839.3 | D28: 2428.95 | E28: 2673.49 | F28: 2812.79 | G28: 2857.32 | H28: 3255.97 | I28: 4038.29 | J28: 5288.87 | K28: 4447.47
A29: Tax | B29: 544.02 | C29: 614.11 | D29: 822.02 | E29: 705.05 | F29: 730.36 | G29: 738.91 | H29: 865.45 | I29: 1039.62 | J29: 1356.03 | K29: 1132.97
A30: Net profit | B30: 1001.36 | C30: 1225.19 | D30: 1606.93 | E30: 1968.44 | F30: 2082.43 | G30: 2118.41 | H30: 2390.52 | I30: 2998.67 | J30: 3932.84 | K30: 3314.5
A31: Dividend Amount | B31: 607.45 | C31: 829.21 | D31: 1108.83 | E31: 3297.56 | F31: 1928.4 | G31: 1928.4 | H31: 2121.24 | I31: 1677.71 | J31: 3104.72 | K31: 2603.34
A40: Quarters
A41: Report Date | B41: 45107 | C41: 45199 | D41: 45291 | E41: 45382 | F41: 45473 | G41: 45565 | H41: 45657 | I41: 45747 | J41: 45838 | K41: 45930
A42: Sales | B42: 4658.53 | C42: 5036.82 | D42: 4600.42 | E42: 5267.59 | F42: 4813.95 | G42: 5104 | H42: 4779.73 | I42: 5503.88 | J42: 5096.16 | K42: 5643.61
A43: Expenses | B43: 3603.01 | C43: 3811.95 | D43: 3505.3 | E43: 3917.54 | F43: 3699.62 | G43: 3936.27 | H43: 3677.04 | I43: 4114.92 | J43: 3995.9 | K43: 4406.97
A44: Other Income | B44: 23.95 | C44: 139.69 | D44: -77 | E44: 36.83 | F44: 39.12 | G44: 297.68 | H44: 4.44 | I44: 8.44 | J44: 4.04 | K44: 1.64
A45: Depreciation | B45: 107.36 | C45: 111.16 | D45: 108.69 | E45: 110.1 | F45: 112.71 | G45: 121.6 | H45: 150.27 | I45: 155.34 | J45: 156.94 | K45: 163.35
A46: Interest | B46: 32.78 | C46: 31.38 | D46: 22.95 | E46: 26.2 | F46: 31.68 | G46: 32.22 | H46: 34.6 | I46: 37.5 | J46: 46.89 | K46: 46.41
A47: Profit before tax | B47: 939.33 | C47: 1222.02 | D47: 886.48 | E47: 1250.58 | F47: 1009.06 | G47: 1311.59 | H47: 922.26 | I47: 1204.56 | J47: 900.47 | K47: 1028.52
A48: Tax | B48: 240.99 | C48: 313.94 | D48: 230.87 | E48: 316.41 | F48: 262.46 | G48: 325.23 | H48: 226.13 | I48: 319.15 | J48: 241.24 | K48: 275.32
A49: Net profit | B49: 698.34 | C49: 908.08 | D49: 655.61 | E49: 934.17 | F49: 746.6 | G49: 986.36 | H49: 696.13 | I49: 885.41 | J49: 659.23 | K49: 753.2
A50: Operating Profit | B50: 1055.52 | C50: 1224.87 | D50: 1095.12 | E50: 1350.05 | F50: 1114.33 | G50: 1167.73 | H50: 1102.69 | I50: 1388.96 | J50: 1100.26 | K50: 1236.64
A55: BALANCE SHEET
A56: Report Date | B56: 42735 | C56: 43100 | D56: 43465 | E56: 43830 | F56: 44196 | G56: 44561 | H56: 44926 | I56: 45291 | J56: 45382 | K56: 45747
A57: Equity Share Capital | B57: 96.42 | C57: 96.42 | D57: 96.42 | E57: 96.42 | F57: 96.42 | G57: 96.42 | H57: 96.42 | I57: 96.42 | J57: 96.42 | K57: 96.42
A58: Reserves | B58: 3185.91 | C58: 3324.17 | D58: 3577.32 | E58: 1822.45 | F58: 1922.92 | G58: 1849.96 | H58: 2362.75 | I58: 2362.75 | J58: 3244.47 | K58: 4020.73
...

Sheet Cash flow Data
C2: 40969 | D2: 41334 | E2: 41699 | F2: 42064 | G2: 42430 | H2: 42795 | I2: 43160 | J2: 43525 | K2: 43891 | L2: 44256 | M2: 44621 | N2: 44986
B3: Cash from Operating Activity - | C3: 18384 | D3: 22163 | E3: 36151 | F3: 35531 | G3: 37900 | H3: 30199 | I3: 23857 | J3: 18891 | K3: 26633 | L3: 29001 | M3: 14283 | N3: 35388
B4: Profit from operations | C4: 22432 | D4: 24406 | E4: 36303 | F4: 43397 | G4: 38626 | H4: 28840 | I4: 33312 | J4: 28771 | K4: 23352 | L4: 31198 | M4: 26943 | N4: 41694
B5: Receivables | C5: -6659 | D5: -5177 | E5: 445 | F5: -3179 | G5: -2223 | H5: -4152 | I5: -10688 | J5: -9109 | K5: 9950 | L5: -5505 | M5: 185 | N5: -2213
B6: Inventory | C6: -2719 | D6: -2656 | E6: -2853 | F6: -3692 | G6: -5743 | H6: -6621 | I6: -3560 | J6: 2069 | K6: 2326 | L6: 3814 | M6: 472 | N6: -5665
B7: Payables | C7: 5867 | D7: 8132 | E7: 4694 | F7: 3598 | G7: 3947 | H7: 9301 | I7: 7320 | J7: -4692 | K7: -8085 | L7: 5748 | M7: -7012 | N7: 6945
B8: Loans Advances | C8: 0 | D8: 0 | E8: 0 | F8: 0 | G8: -520 | H8: 0 | I8: 0 | J8: 0 | K8: 0 | L8: 0 | M8: 0 | N8: 0
B9: Other WC items | C9: 1231 | D9: -303 | E9: 1870 | F9: -398 | G9: 5852 | H9: 4727 | I9: 494 | J9: 4512 | K9: 875 | L9: -4150 | M9: -4396 | N9: -2194
B10: Working capital changes | C10: -2280 | D10: -3 | E10: 4157 | F10: -3672 | G10: 1313 | H10: 3254 | I10: -6434 | J10: -7221 | K10: 5065 | L10: -93 | M10: -10750 | N10: -3127
B11: Direct taxes | C11: -1768 | D11: -2240 | E11: -4308 | F11: -4194 | G11: -2040 | H11: -1895 | I11: -3021 | J11: -2659 | K11: -1785 | L11: -2105 | M11: -1910 | N11: -3179
B12: Cash from Investing Activity - | C12: -19464 | D12: -22969 | E12: -27991 | F12: -36232 | G12: -36694 | H12: -39571 | I12: -25139 | J12: -20878 | K12: -33115 | L12: -25672 | M12: -4444 | N12: -15417
B13: Fixed assets purchased | C13: -13876 | D13: -18863 | E13: -26975 | F13: -31962 | G13: -31503 | H13: -16072 | I13: -35079 | J13: -35304 | K13: -29702 | L13: -20205 | M13: -15168 | N13: -19230
B14: Fixed assets sold | C14: 93 | D14: 37 | E14: 50 | F14: 74 | G14: 59 | H14: 53 | I14: 30 | J14: 67 | K14: 171 | L14: 351 | M14: 230 | N14: 285
... B34: Net Cash Flow | C34: 5488 | D34: -2499 | E34: 4277 | F34: 4500 | G34: -2589 | H34: -3167 | I34: 730 | J34: 6843 | K34: -3092 | L34: 13232 | M34: 6459 | N34: -6272
